T13330: Successful exception
CallStack (from HasCallStack):
  error, called at T13330.hs:5:16 in main:Main
HasCallStack backtrace:
    collectBacktraces, called at libraries/ghc-internal/src/GHC/Internal/Exception.hs:92:13 in ghc-internal:GHC.Internal.Exception
    toExceptionWithBacktrace, called at libraries/ghc-internal/src/GHC/Internal/Exception.hs:128:3 in ghc-internal:GHC.Internal.Exception



